Workbook

Sheet README
A1: Home Mortgage Calculator
A3: How to use:
A4: 1. Open the Inputs sheet and edit the YELLOW cells (blue text).
A5: 2. All other sheets update automatically.
A7: Sheets:
A8: • Inputs — All editable assumptions. Includes monthly payment summary.
A9: • Amortization — Full 360-month schedule. PMI auto-deactivates at 20% LTV.
A10: • Appreciation — Year-by-year asset value, equity, and cumulative interest. Includes chart.
A11: • Rent vs Buy — Net wealth path (with escalating tax + insurance). Includes chart.
A12: • Affordability — Minimum household income required at conventional DTI standards.
A13: • Cash to Close — Cash needed at closing and recommended liquid retention.
A14: • Buy Today — Liquidity check and concentration cap analysis.
... A39: • Cost basis adjustments for capital improvements

Sheet Inputs
A1: Home Mortgage Calculator — Inputs
A2: Blue cells = editable assumptions. All other sheets pull from this one.
A4: LOAN
A5: Home price ($) | B5: 500000 | C5: Purchase price of the home
A6: Down payment (%) | B6: 0.2 | C6: % of price paid up-front
A7: Interest rate (annual %) | B7: 0.065 | C7: APR — fixed-rate mortgage
A8: Loan term (years) | B8: 30 | C8: Common: 15, 20, 30
A9: RECURRING COSTS
A10: Property tax (annual %) | B10: 0.012 | C10: Typical: 0.5–2.0% of home value
A11: Home insurance ($/year) | B11: 1800 | C11: Annual premium
A12: HOA ($/month) | B12: 0 | C12: $0 if no HOA
A13: PMI rate (annual %) | B13: 0.006 | C13: Usually 0.3–1.5%; only applies if down < 20%
A14: APPRECIATION & COSTS
A15: Home appreciation (annual %) | B15: 0.035 | C15: Long-run US avg ~3–4%
A16: Maintenance (% of home value/yr) | B16: 0.01 | C16: Rule of thumb: 1%/yr
A17: Closing costs (% of price) | B17: 0.03 | C17: Typical: 2–5%
A18: Selling costs (% of sale) | B18: 0.06 | C18: Typical: 6% (agent fees etc)
A19: EXTRA PAYMENTS
A20: Extra monthly principal ($) | B20: 0 | C20: Additional principal each month
A21: RENT VS. BUY
A22: Current rent ($/month) | B22: 2500 | C22: What you'd pay if renting
A23: Annual rent increase (%) | B23: 0.03 | C23: Typical: 2–4%
A24: Investment return (%) | B24: 0.07 | C24: Opportunity cost of down payment
A25: AFFORDABILITY
A26: Other monthly debts ($) | B26: 0 | C26: Car, student loans, credit card min etc.
A27: Custom front-end DTI (%) | B27: 0.28 | C27: Your housing-to-income ceiling
A28: ESCALATION
A29: Property tax growth (annual %) | B29: 0.02 | C29: How fast tax grows; CA Prop 13 caps at 2%
A30: Insurance growth (annual %) | B30: 0.05 | C30: Often 4-7%; higher in climate-affected areas
A31: CASH TO CLOSE
A32: Initial repairs / move-in ($) | B32: 5000 | C32: Lump-sum at move-in: furniture, repairs etc.
A33: Required reserves (months PITI) | B33: 2 | C33: Lenders want 2-6 months of PITI in reserves
A34: SAVINGS & ASSETS
A35: Current liquid assets ($) | B35: 150000 | C35: Cash + brokerage + savings (excl. retirement)
A36: Monthly savings ($/mo) | B36: 2000 | C36: What you can save toward the down payment
A37: Monthly household expenses ($) | B37: 6000 | C37: Food, utilities, transport — excl. mortgage
A38: Emergency fund target (months) | B38: 6 | C38: Recommended: 6 months of expenses
A39: Max % of liquid for down payment | B39: 0.5 | C39: Concentration cap — don't lock more than this share into one asset
A40: TAXES
A41: Filing status (M=married, S=single) | B41: M | C41: M = MFJ ($500K cap gains excl.); S = Single ($250K)
...

Sheet Amortization
A1: Amortization Schedule
A2: Formulas reference the Inputs sheet. Edit assumptions there to update everything.
A4: Month | B4: Year | C4: Beginning Balance | D4: Payment | E4: Principal | F4: Interest | G4: Extra Principal | H4: PMI Active? | I4: Ending Balance
A5: 1 | B5: =CEILING(A5/12,1) | C5: =Inputs!$B$63 | D5: =IF(AND(C5>0.01,A5<=Inputs!$B$65),Inputs!$B$66,0) | E5: =IF(D5=0,0,MIN(D5-F5,C5)) | F5: =IF(C5>0.01,C5*Inputs!$B$64,0) | G5: =IF(C5-E5>0,MIN(Inputs!$B$20,C5-E5),0) | H5: =IF(Inputs!$B$62+SUM(E$5:E5)+SUM(G$5:G5)<Inputs!$B$72,1,0) | I5: =MAX(0,C5-E5-G5)
A6: 2 | B6: =CEILING(A6/12,1) | C6: =I5 | D6: =IF(AND(C6>0.01,A6<=Inputs!$B$65),Inputs!$B$66,0) | E6: =IF(D6=0,0,MIN(D6-F6,C6)) | F6: =IF(C6>0.01,C6*Inputs!$B$64,0) | G6: =IF(C6-E6>0,MIN(Inputs!$B$20,C6-E6),0) | H6: =IF(Inputs!$B$62+SUM(E$5:E6)+SUM(G$5:G5)<Inputs!$B$72,1,0) | I6: =MAX(0,C6-E6-G6)
A7: 3 | B7: =CEILING(A7/12,1) | C7: =I6 | D7: =IF(AND(C7>0.01,A7<=Inputs!$B$65),Inputs!$B$66,0) | E7: =IF(D7=0,0,MIN(D7-F7,C7)) | F7: =IF(C7>0.01,C7*Inputs!$B$64,0) | G7: =IF(C7-E7>0,MIN(Inputs!$B$20,C7-E7),0) | H7: =IF(Inputs!$B$62+SUM(E$5:E7)+SUM(G$5:G6)<Inputs!$B$72,1,0) | I7: =MAX(0,C7-E7-G7)
A8: 4 | B8: =CEILING(A8/12,1) | C8: =I7 | D8: =IF(AND(C8>0.01,A8<=Inputs!$B$65),Inputs!$B$66,0) | E8: =IF(D8=0,0,MIN(D8-F8,C8)) | F8: =IF(C8>0.01,C8*Inputs!$B$64,0) | G8: =IF(C8-E8>0,MIN(Inputs!$B$20,C8-E8),0) | H8: =IF(Inputs!$B$62+SUM(E$5:E8)+SUM(G$5:G7)<Inputs!$B$72,1,0) | I8: =MAX(0,C8-E8-G8)
A9: 5 | B9: =CEILING(A9/12,1) | C9: =I8 | D9: =IF(AND(C9>0.01,A9<=Inputs!$B$65),Inputs!$B$66,0) | E9: =IF(D9=0,0,MIN(D9-F9,C9)) | F9: =IF(C9>0.01,C9*Inputs!$B$64,0) | G9: =IF(C9-E9>0,MIN(Inputs!$B$20,C9-E9),0) | H9: =IF(Inputs!$B$62+SUM(E$5:E9)+SUM(G$5:G8)<Inputs!$B$72,1,0) | I9: =MAX(0,C9-E9-G9)
A10: 6 | B10: =CEILING(A10/12,1) | C10: =I9 | D10: =IF(AND(C10>0.01,A10<=Inputs!$B$65),Inputs!$B$66,0) | E10: =IF(D10=0,0,MIN(D10-F10,C10)) | F10: =IF(C10>0.01,C10*Inputs!$B$64,0) | G10: =IF(C10-E10>0,MIN(Inputs!$B$20,C10-E10),0) | H10: =IF(Inputs!$B$62+SUM(E$5:E10)+SUM(G$5:G9)<Inputs!$B$72,1,0) | I10: =MAX(0,C10-E10-G10)
A11: 7 | B11: =CEILING(A11/12,1) | C11: =I10 | D11: =IF(AND(C11>0.01,A11<=Inputs!$B$65),Inputs!$B$66,0) | E11: =IF(D11=0,0,MIN(D11-F11,C11)) | F11: =IF(C11>0.01,C11*Inputs!$B$64,0) | G11: =IF(C11-E11>0,MIN(Inputs!$B$20,C11-E11),0) | H11: =IF(Inputs!$B$62+SUM(E$5:E11)+SUM(G$5:G10)<Inputs!$B$72,1,0) | I11: =MAX(0,C11-E11-G11)
A12: 8 | B12: =CEILING(A12/12,1) | C12: =I11 | D12: =IF(AND(C12>0.01,A12<=Inputs!$B$65),Inputs!$B$66,0) | E12: =IF(D12=0,0,MIN(D12-F12,C12)) | F12: =IF(C12>0.01,C12*Inputs!$B$64,0) | G12: =IF(C12-E12>0,MIN(Inputs!$B$20,C12-E12),0) | H12: =IF(Inputs!$B$62+SUM(E$5:E12)+SUM(G$5:G11)<Inputs!$B$72,1,0) | I12: =MAX(0,C12-E12-G12)
A13: 9 | B13: =CEILING(A13/12,1) | C13: =I12 | D13: =IF(AND(C13>0.01,A13<=Inputs!$B$65),Inputs!$B$66,0) | E13: =IF(D13=0,0,MIN(D13-F13,C13)) | F13: =IF(C13>0.01,C13*Inputs!$B$64,0) | G13: =IF(C13-E13>0,MIN(Inputs!$B$20,C13-E13),0) | H13: =IF(Inputs!$B$62+SUM(E$5:E13)+SUM(G$5:G12)<Inputs!$B$72,1,0) | I13: =MAX(0,C13-E13-G13)
A14: 10 | B14: =CEILING(A14/12,1) | C14: =I13 | D14: =IF(AND(C14>0.01,A14<=Inputs!$B$65),Inputs!$B$66,0) | E14: =IF(D14=0,0,MIN(D14-F14,C14)) | F14: =IF(C14>0.01,C14*Inputs!$B$64,0) | G14: =IF(C14-E14>0,MIN(Inputs!$B$20,C14-E14),0) | H14: =IF(Inputs!$B$62+SUM(E$5:E14)+SUM(G$5:G13)<Inputs!$B$72,1,0) | I14: =MAX(0,C14-E14-G14)
A15: 11 | B15: =CEILING(A15/12,1) | C15: =I14 | D15: =IF(AND(C15>0.01,A15<=Inputs!$B$65),Inputs!$B$66,0) | E15: =IF(D15=0,0,MIN(D15-F15,C15)) | F15: =IF(C15>0.01,C15*Inputs!$B$64,0) | G15: =IF(C15-E15>0,MIN(Inputs!$B$20,C15-E15),0) | H15: =IF(Inputs!$B$62+SUM(E$5:E15)+SUM(G$5:G14)<Inputs!$B$72,1,0) | I15: =MAX(0,C15-E15-G15)
A16: 12 | B16: =CEILING(A16/12,1) | C16: =I15 | D16: =IF(AND(C16>0.01,A16<=Inputs!$B$65),Inputs!$B$66,0) | E16: =IF(D16=0,0,MIN(D16-F16,C16)) | F16: =IF(C16>0.01,C16*Inputs!$B$64,0) | G16: =IF(C16-E16>0,MIN(Inputs!$B$20,C16-E16),0) | H16: =IF(Inputs!$B$62+SUM(E$5:E16)+SUM(G$5:G15)<Inputs!$B$72,1,0) | I16: =MAX(0,C16-E16-G16)
A17: 13 | B17: =CEILING(A17/12,1) | C17: =I16 | D17: =IF(AND(C17>0.01,A17<=Inputs!$B$65),Inputs!$B$66,0) | E17: =IF(D17=0,0,MIN(D17-F17,C17)) | F17: =IF(C17>0.01,C17*Inputs!$B$64,0) | G17: =IF(C17-E17>0,MIN(Inputs!$B$20,C17-E17),0) | H17: =IF(Inputs!$B$62+SUM(E$5:E17)+SUM(G$5:G16)<Inputs!$B$72,1,0) | I17: =MAX(0,C17-E17-G17)
... A364: 360 | B364: =CEILING(A364/12,1) | C364: =I363 | D364: =IF(AND(C364>0.01,A364<=Inputs!$B$65),Inputs!$B$66,0) | E364: =IF(D364=0,0,MIN(D364-F364,C364)) | F364: =IF(C364>0.01,C364*Inputs!$B$64,0) | G364: =IF(C364-E364>0,MIN(Inputs!$B$20,C364-E364),0) | H364: =IF(Inputs!$B$62+SUM(E$5:E364)+SUM(G$5:G363)<Inputs!$B$72,1,0) | I364: =MAX(0,C364-E364-G364)
A366: TOTAL | D366: =SUM(D5:D365) | E366: =SUM(E5:E365) | F366: =SUM(F5:F365) | G366: =SUM(G5:G365)

Sheet Appreciation
A1: Home Appreciation & Equity
A2: Year-by-year asset projection. Net equity = appreciated value − loan balance − selling costs.
A4: Year | B4: Home Value | C4: Loan Balance | D4: Gross Equity | E4: Selling Costs | F4: Net Equity | G4: Cum. Interest | H4: Cum. Principal
A5: 1 | B5: =Inputs!$B$5*(1+Inputs!$B$15)^A5 | C5: =IFERROR(INDEX(Amortization!I:I,MIN(16,364)),0) | D5: =B5-C5 | E5: =B5*Inputs!$B$18 | F5: =D5-E5 | G5: =SUM(Amortization!F$5:INDEX(Amortization!F:F,MIN(16,364))) | H5: =SUM(Amortization!E$5:INDEX(Amortization!E:E,MIN(16,364)))+SUM(Amortization!G$5:INDEX(Amortization!G:G,MIN(16,364)))
A6: 2 | B6: =Inputs!$B$5*(1+Inputs!$B$15)^A6 | C6: =IFERROR(INDEX(Amortization!I:I,MIN(28,364)),0) | D6: =B6-C6 | E6: =B6*Inputs!$B$18 | F6: =D6-E6 | G6: =SUM(Amortization!F$5:INDEX(Amortization!F:F,MIN(28,364))) | H6: =SUM(Amortization!E$5:INDEX(Amortization!E:E,MIN(28,364)))+SUM(Amortization!G$5:INDEX(Amortization!G:G,MIN(28,364)))
A7: 3 | B7: =Inputs!$B$5*(1+Inputs!$B$15)^A7 | C7: =IFERROR(INDEX(Amortization!I:I,MIN(40,364)),0) | D7: =B7-C7 | E7: =B7*Inputs!$B$18 | F7: =D7-E7 | G7: =SUM(Amortization!F$5:INDEX(Amortization!F:F,MIN(40,364))) | H7: =SUM(Amortization!E$5:INDEX(Amortization!E:E,MIN(40,364)))+SUM(Amortization!G$5:INDEX(Amortization!G:G,MIN(40,364)))
A8: 4 | B8: =Inputs!$B$5*(1+Inputs!$B$15)^A8 | C8: =IFERROR(INDEX(Amortization!I:I,MIN(52,364)),0) | D8: =B8-C8 | E8: =B8*Inputs!$B$18 | F8: =D8-E8 | G8: =SUM(Amortization!F$5:INDEX(Amortization!F:F,MIN(52,364))) | H8: =SUM(Amortization!E$5:INDEX(Amortization!E:E,MIN(52,364)))+SUM(Amortization!G$5:INDEX(Amortization!G:G,MIN(52,364)))
A9: 5 | B9: =Inputs!$B$5*(1+Inputs!$B$15)^A9 | C9: =IFERROR(INDEX(Amortization!I:I,MIN(64,364)),0) | D9: =B9-C9 | E9: =B9*Inputs!$B$18 | F9: =D9-E9 | G9: =SUM(Amortization!F$5:INDEX(Amortization!F:F,MIN(64,364))) | H9: =SUM(Amortization!E$5:INDEX(Amortization!E:E,MIN(64,364)))+SUM(Amortization!G$5:INDEX(Amortization!G:G,MIN(64,364)))
A10: 6 | B10: =Inputs!$B$5*(1+Inputs!$B$15)^A10 | C10: =IFERROR(INDEX(Amortization!I:I,MIN(76,364)),0) | D10: =B10-C10 | E10: =B10*Inputs!$B$18 | F10: =D10-E10 | G10: =SUM(Amortization!F$5:INDEX(Amortization!F:F,MIN(76,364))) | H10: =SUM(Amortization!E$5:INDEX(Amortization!E:E,MIN(76,364)))+SUM(Amortization!G$5:INDEX(Amortization!G:G,MIN(76,364)))
A11: 7 | B11: =Inputs!$B$5*(1+Inputs!$B$15)^A11 | C11: =IFERROR(INDEX(Amortization!I:I,MIN(88,364)),0) | D11: =B11-C11 | E11: =B11*Inputs!$B$18 | F11: =D11-E11 | G11: =SUM(Amortization!F$5:INDEX(Amortization!F:F,MIN(88,364))) | H11: =SUM(Amortization!E$5:INDEX(Amortization!E:E,MIN(88,364)))+SUM(Amortization!G$5:INDEX(Amortization!G:G,MIN(88,364)))
A12: 8 | B12: =Inputs!$B$5*(1+Inputs!$B$15)^A12 | C12: =IFERROR(INDEX(Amortization!I:I,MIN(100,364)),0) | D12: =B12-C12 | E12: =B12*Inputs!$B$18 | F12: =D12-E12 | G12: =SUM(Amortization!F$5:INDEX(Amortization!F:F,MIN(100,364))) | H12: =SUM(Amortization!E$5:INDEX(Amortization!E:E,MIN(100,364)))+SUM(Amortization!G$5:INDEX(Amortization!G:G,MIN(100,364)))
A13: 9 | B13: =Inputs!$B$5*(1+Inputs!$B$15)^A13 | C13: =IFERROR(INDEX(Amortization!I:I,MIN(112,364)),0) | D13: =B13-C13 | E13: =B13*Inputs!$B$18 | F13: =D13-E13 | G13: =SUM(Amortization!F$5:INDEX(Amortization!F:F,MIN(112,364))) | H13: =SUM(Amortization!E$5:INDEX(Amortization!E:E,MIN(112,364)))+SUM(Amortization!G$5:INDEX(Amortization!G:G,MIN(112,364)))
A14: 10 | B14: =Inputs!$B$5*(1+Inputs!$B$15)^A14 | C14: =IFERROR(INDEX(Amortization!I:I,MIN(124,364)),0) | D14: =B14-C14 | E14: =B14*Inputs!$B$18 | F14: =D14-E14 | G14: =SUM(Amortization!F$5:INDEX(Amortization!F:F,MIN(124,364))) | H14: =SUM(Amortization!E$5:INDEX(Amortization!E:E,MIN(124,364)))+SUM(Amortization!G$5:INDEX(Amortization!G:G,MIN(124,364)))
A15: 11 | B15: =Inputs!$B$5*(1+Inputs!$B$15)^A15 | C15: =IFERROR(INDEX(Amortization!I:I,MIN(136,364)),0) | D15: =B15-C15 | E15: =B15*Inputs!$B$18 | F15: =D15-E15 | G15: =SUM(Amortization!F$5:INDEX(Amortization!F:F,MIN(136,364))) | H15: =SUM(Amortization!E$5:INDEX(Amortization!E:E,MIN(136,364)))+SUM(Amortization!G$5:INDEX(Amortization!G:G,MIN(136,364)))
A16: 12 | B16: =Inputs!$B$5*(1+Inputs!$B$15)^A16 | C16: =IFERROR(INDEX(Amortization!I:I,MIN(148,364)),0) | D16: =B16-C16 | E16: =B16*Inputs!$B$18 | F16: =D16-E16 | G16: =SUM(Amortization!F$5:INDEX(Amortization!F:F,MIN(148,364))) | H16: =SUM(Amortization!E$5:INDEX(Amortization!E:E,MIN(148,364)))+SUM(Amortization!G$5:INDEX(Amortization!G:G,MIN(148,364)))
A17: 13 | B17: =Inputs!$B$5*(1+Inputs!$B$15)^A17 | C17: =IFERROR(INDEX(Amortization!I:I,MIN(160,364)),0) | D17: =B17-C17 | E17: =B17*Inputs!$B$18 | F17: =D17-E17 | G17: =SUM(Amortization!F$5:INDEX(Amortization!F:F,MIN(160,364))) | H17: =SUM(Amortization!E$5:INDEX(Amortization!E:E,MIN(160,364)))+SUM(Amortization!G$5:INDEX(Amortization!G:G,MIN(160,364)))
A18: 14 | B18: =Inputs!$B$5*(1+Inputs!$B$15)^A18 | C18: =IFERROR(INDEX(Amortization!I:I,MIN(172,364)),0) | D18: =B18-C18 | E18: =B18*Inputs!$B$18 | F18: =D18-E18 | G18: =SUM(Amortization!F$5:INDEX(Amortization!F:F,MIN(172,364))) | H18: =SUM(Amortization!E$5:INDEX(Amortization!E:E,MIN(172,364)))+SUM(Amortization!G$5:INDEX(Amortization!G:G,MIN(172,364)))
A19: 15 | B19: =Inputs!$B$5*(1+Inputs!$B$15)^A19 | C19: =IFERROR(INDEX(Amortization!I:I,MIN(184,364)),0) | D19: =B19-C19 | E19: =B19*Inputs!$B$18 | F19: =D19-E19 | G19: =SUM(Amortization!F$5:INDEX(Amortization!F:F,MIN(184,364))) | H19: =SUM(Amortization!E$5:INDEX(Amortization!E:E,MIN(184,364)))+SUM(Amortization!G$5:INDEX(Amortization!G:G,MIN(184,364)))
A20: 16 | B20: =Inputs!$B$5*(1+Inputs!$B$15)^A20 | C20: =IFERROR(INDEX(Amortization!I:I,MIN(196,364)),0) | D20: =B20-C20 | E20: =B20*Inputs!$B$18 | F20: =D20-E20 | G20: =SUM(Amortization!F$5:INDEX(Amortization!F:F,MIN(196,364))) | H20: =SUM(Amortization!E$5:INDEX(Amortization!E:E,MIN(196,364)))+SUM(Amortization!G$5:INDEX(Amortization!G:G,MIN(196,364)))
A21: 17 | B21: =Inputs!$B$5*(1+Inputs!$B$15)^A21 | C21: =IFERROR(INDEX(Amortization!I:I,MIN(208,364)),0) | D21: =B21-C21 | E21: =B21*Inputs!$B$18 | F21: =D21-E21 | G21: =SUM(Amortization!F$5:INDEX(Amortization!F:F,MIN(208,364))) | H21: =SUM(Amortization!E$5:INDEX(Amortization!E:E,MIN(208,364)))+SUM(Amortization!G$5:INDEX(Amortization!G:G,MIN(208,364)))
A22: 18 | B22: =Inputs!$B$5*(1+Inputs!$B$15)^A22 | C22: =IFERROR(INDEX(Amortization!I:I,MIN(220,364)),0) | D22: =B22-C22 | E22: =B22*Inputs!$B$18 | F22: =D22-E22 | G22: =SUM(Amortization!F$5:INDEX(Amortization!F:F,MIN(220,364))) | H22: =SUM(Amortization!E$5:INDEX(Amortization!E:E,MIN(220,364)))+SUM(Amortization!G$5:INDEX(Amortization!G:G,MIN(220,364)))
A23: 19 | B23: =Inputs!$B$5*(1+Inputs!$B$15)^A23 | C23: =IFERROR(INDEX(Amortization!I:I,MIN(232,364)),0) | D23: =B23-C23 | E23: =B23*Inputs!$B$18 | F23: =D23-E23 | G23: =SUM(Amortization!F$5:INDEX(Amortization!F:F,MIN(232,364))) | H23: =SUM(Amortization!E$5:INDEX(Amortization!E:E,MIN(232,364)))+SUM(Amortization!G$5:INDEX(Amortization!G:G,MIN(232,364)))
A24: 20 | B24: =Inputs!$B$5*(1+Inputs!$B$15)^A24 | C24: =IFERROR(INDEX(Amortization!I:I,MIN(244,364)),0) | D24: =B24-C24 | E24: =B24*Inputs!$B$18 | F24: =D24-E24 | G24: =SUM(Amortization!F$5:INDEX(Amortization!F:F,MIN(244,364))) | H24: =SUM(Amortization!E$5:INDEX(Amortization!E:E,MIN(244,364)))+SUM(Amortization!G$5:INDEX(Amortization!G:G,MIN(244,364)))
A25: 21 | B25: =Inputs!$B$5*(1+Inputs!$B$15)^A25 | C25: =IFERROR(INDEX(Amortization!I:I,MIN(256,364)),0) | D25: =B25-C25 | E25: =B25*Inputs!$B$18 | F25: =D25-E25 | G25: =SUM(Amortization!F$5:INDEX(Amortization!F:F,MIN(256,364))) | H25: =SUM(Amortization!E$5:INDEX(Amortization!E:E,MIN(256,364)))+SUM(Amortization!G$5:INDEX(Amortization!G:G,MIN(256,364)))
A26: 22 | B26: =Inputs!$B$5*(1+Inputs!$B$15)^A26 | C26: =IFERROR(INDEX(Amortization!I:I,MIN(268,364)),0) | D26: =B26-C26 | E26: =B26*Inputs!$B$18 | F26: =D26-E26 | G26: =SUM(Amortization!F$5:INDEX(Amortization!F:F,MIN(268,364))) | H26: =SUM(Amortization!E$5:INDEX(Amortization!E:E,MIN(268,364)))+SUM(Amortization!G$5:INDEX(Amortization!G:G,MIN(268,364)))
A27: 23 | B27: =Inputs!$B$5*(1+Inputs!$B$15)^A27 | C27: =IFERROR(INDEX(Amortization!I:I,MIN(280,364)),0) | D27: =B27-C27 | E27: =B27*Inputs!$B$18 | F27: =D27-E27 | G27: =SUM(Amortization!F$5:INDEX(Amortization!F:F,MIN(280,364))) | H27: =SUM(Amortization!E$5:INDEX(Amortization!E:E,MIN(280,364)))+SUM(Amortization!G$5:INDEX(Amortization!G:G,MIN(280,364)))
A28: 24 | B28: =Inputs!$B$5*(1+Inputs!$B$15)^A28 | C28: =IFERROR(INDEX(Amortization!I:I,MIN(292,364)),0) | D28: =B28-C28 | E28: =B28*Inputs!$B$18 | F28: =D28-E28 | G28: =SUM(Amortization!F$5:INDEX(Amortization!F:F,MIN(292,364))) | H28: =SUM(Amortization!E$5:INDEX(Amortization!E:E,MIN(292,364)))+SUM(Amortization!G$5:INDEX(Amortization!G:G,MIN(292,364)))
A29: 25 | B29: =Inputs!$B$5*(1+Inputs!$B$15)^A29 | C29: =IFERROR(INDEX(Amortization!I:I,MIN(304,364)),0) | D29: =B29-C29 | E29: =B29*Inputs!$B$18 | F29: =D29-E29 | G29: =SUM(Amortization!F$5:INDEX(Amortization!F:F,MIN(304,364))) | H29: =SUM(Amortization!E$5:INDEX(Amortization!E:E,MIN(304,364)))+SUM(Amortization!G$5:INDEX(Amortization!G:G,MIN(304,364)))
A30: 26 | B30: =Inputs!$B$5*(1+Inputs!$B$15)^A30 | C30: =IFERROR(INDEX(Amortization!I:I,MIN(316,364)),0) | D30: =B30-C30 | E30: =B30*Inputs!$B$18 | F30: =D30-E30 | G30: =SUM(Amortization!F$5:INDEX(Amortization!F:F,MIN(316,364))) | H30: =SUM(Amortization!E$5:INDEX(Amortization!E:E,MIN(316,364)))+SUM(Amortization!G$5:INDEX(Amortization!G:G,MIN(316,364)))
A31: 27 | B31: =Inputs!$B$5*(1+Inputs!$B$15)^A31 | C31: =IFERROR(INDEX(Amortization!I:I,MIN(328,364)),0) | D31: =B31-C31 | E31: =B31*Inputs!$B$18 | F31: =D31-E31 | G31: =SUM(Amortization!F$5:INDEX(Amortization!F:F,MIN(328,364))) | H31: =SUM(Amortization!E$5:INDEX(Amortization!E:E,MIN(328,364)))+SUM(Amortization!G$5:INDEX(Amortization!G:G,MIN(328,364)))
A32: 28 | B32: =Inputs!$B$5*(1+Inputs!$B$15)^A32 | C32: =IFERROR(INDEX(Amortization!I:I,MIN(340,364)),0) | D32: =B32-C32 | E32: =B32*Inputs!$B$18 | F32: =D32-E32 | G32: =SUM(Amortization!F$5:INDEX(Amortization!F:F,MIN(340,364))) | H32: =SUM(Amortization!E$5:INDEX(Amortization!E:E,MIN(340,364)))+SUM(Amortization!G$5:INDEX(Amortization!G:G,MIN(340,364)))
A33: 29 | B33: =Inputs!$B$5*(1+Inputs!$B$15)^A33 | C33: =IFERROR(INDEX(Amortization!I:I,MIN(352,364)),0) | D33: =B33-C33 | E33: =B33*Inputs!$B$18 | F33: =D33-E33 | G33: =SUM(Amortization!F$5:INDEX(Amortization!F:F,MIN(352,364))) | H33: =SUM(Amortization!E$5:INDEX(Amortization!E:E,MIN(352,364)))+SUM(Amortization!G$5:INDEX(Amortization!G:G,MIN(352,364)))
A34: 30 | B34: =Inputs!$B$5*(1+Inputs!$B$15)^A34 | C34: =IFERROR(INDEX(Amortization!I:I,MIN(364,364)),0) | D34: =B34-C34 | E34: =B34*Inputs!$B$18 | F34: =D34-E34 | G34: =SUM(Amortization!F$5:INDEX(Amortization!F:F,MIN(364,364))) | H34: =SUM(Amortization!E$5:INDEX(Amortization!E:E,MIN(364,364)))+SUM(Amortization!G$5:INDEX(Amortization!G:G,MIN(364,364)))

Sheet Rent vs Buy
A1: Rent vs. Buy Comparison
A2: Compares net wealth path of buying (net equity − ownership costs) vs. renting (down payment invested − rent paid).
A4: Year | B4: Annual Buy Cost | C4: Cum. Buy Cost | D4: Annual Rent | E4: Cum. Rent | F4: Investment Acct | G4: Buy Net Wealth | H4: Rent Net Wealth | I4: Buy − Rent
A5: 1 | B5: =SUM(Amortization!D5:D16)+SUM(Amortization!G5:G16)+12*(Inputs!$B$67*(1+Inputs!$B$29)^(A5-1)+Inputs!$B$68*(1+Inputs!$B$30)^(A5-1)+Inputs!$B$70)+SUM(Amortization!H5:H16)*Inputs!$B$69+Inputs!$B$16*Appreciation!B5 | C5: =Inputs!$B$71+B5 | D5: =Inputs!$B$22*12*(1+Inputs!$B$23)^(A5-1) | E5: =D5 | F5: =(Inputs!$B$62+Inputs!$B$71)*(1+Inputs!$B$24)^A5 | G5: =Appreciation!F5-C5 | H5: =F5-E5 | I5: =G5-H5
A6: 2 | B6: =SUM(Amortization!D17:D28)+SUM(Amortization!G17:G28)+12*(Inputs!$B$67*(1+Inputs!$B$29)^(A6-1)+Inputs!$B$68*(1+Inputs!$B$30)^(A6-1)+Inputs!$B$70)+SUM(Amortization!H17:H28)*Inputs!$B$69+Inputs!$B$16*Appreciation!B6 | C6: =C5+B6 | D6: =Inputs!$B$22*12*(1+Inputs!$B$23)^(A6-1) | E6: =E5+D6 | F6: =(Inputs!$B$62+Inputs!$B$71)*(1+Inputs!$B$24)^A6 | G6: =Appreciation!F6-C6 | H6: =F6-E6 | I6: =G6-H6
A7: 3 | B7: =SUM(Amortization!D29:D40)+SUM(Amortization!G29:G40)+12*(Inputs!$B$67*(1+Inputs!$B$29)^(A7-1)+Inputs!$B$68*(1+Inputs!$B$30)^(A7-1)+Inputs!$B$70)+SUM(Amortization!H29:H40)*Inputs!$B$69+Inputs!$B$16*Appreciation!B7 | C7: =C6+B7 | D7: =Inputs!$B$22*12*(1+Inputs!$B$23)^(A7-1) | E7: =E6+D7 | F7: =(Inputs!$B$62+Inputs!$B$71)*(1+Inputs!$B$24)^A7 | G7: =Appreciation!F7-C7 | H7: =F7-E7 | I7: =G7-H7
A8: 4 | B8: =SUM(Amortization!D41:D52)+SUM(Amortization!G41:G52)+12*(Inputs!$B$67*(1+Inputs!$B$29)^(A8-1)+Inputs!$B$68*(1+Inputs!$B$30)^(A8-1)+Inputs!$B$70)+SUM(Amortization!H41:H52)*Inputs!$B$69+Inputs!$B$16*Appreciation!B8 | C8: =C7+B8 | D8: =Inputs!$B$22*12*(1+Inputs!$B$23)^(A8-1) | E8: =E7+D8 | F8: =(Inputs!$B$62+Inputs!$B$71)*(1+Inputs!$B$24)^A8 | G8: =Appreciation!F8-C8 | H8: =F8-E8 | I8: =G8-H8
A9: 5 | B9: =SUM(Amortization!D53:D64)+SUM(Amortization!G53:G64)+12*(Inputs!$B$67*(1+Inputs!$B$29)^(A9-1)+Inputs!$B$68*(1+Inputs!$B$30)^(A9-1)+Inputs!$B$70)+SUM(Amortization!H53:H64)*Inputs!$B$69+Inputs!$B$16*Appreciation!B9 | C9: =C8+B9 | D9: =Inputs!$B$22*12*(1+Inputs!$B$23)^(A9-1) | E9: =E8+D9 | F9: =(Inputs!$B$62+Inputs!$B$71)*(1+Inputs!$B$24)^A9 | G9: =Appreciation!F9-C9 | H9: =F9-E9 | I9: =G9-H9
A10: 6 | B10: =SUM(Amortization!D65:D76)+SUM(Amortization!G65:G76)+12*(Inputs!$B$67*(1+Inputs!$B$29)^(A10-1)+Inputs!$B$68*(1+Inputs!$B$30)^(A10-1)+Inputs!$B$70)+SUM(Amortization!H65:H76)*Inputs!$B$69+Inputs!$B$16*Appreciation!B10 | C10: =C9+B10 | D10: =Inputs!$B$22*12*(1+Inputs!$B$23)^(A10-1) | E10: =E9+D10 | F10: =(Inputs!$B$62+Inputs!$B$71)*(1+Inputs!$B$24)^A10 | G10: =Appreciation!F10-C10 | H10: =F10-E10 | I10: =G10-H10
A11: 7 | B11: =SUM(Amortization!D77:D88)+SUM(Amortization!G77:G88)+12*(Inputs!$B$67*(1+Inputs!$B$29)^(A11-1)+Inputs!$B$68*(1+Inputs!$B$30)^(A11-1)+Inputs!$B$70)+SUM(Amortization!H77:H88)*Inputs!$B$69+Inputs!$B$16*Appreciation!B11 | C11: =C10+B11 | D11: =Inputs!$B$22*12*(1+Inputs!$B$23)^(A11-1) | E11: =E10+D11 | F11: =(Inputs!$B$62+Inputs!$B$71)*(1+Inputs!$B$24)^A11 | G11: =Appreciation!F11-C11 | H11: =F11-E11 | I11: =G11-H11
A12: 8 | B12: =SUM(Amortization!D89:D100)+SUM(Amortization!G89:G100)+12*(Inputs!$B$67*(1+Inputs!$B$29)^(A12-1)+Inputs!$B$68*(1+Inputs!$B$30)^(A12-1)+Inputs!$B$70)+SUM(Amortization!H89:H100)*Inputs!$B$69+Inputs!$B$16*Appreciation!B12 | C12: =C11+B12 | D12: =Inputs!$B$22*12*(1+Inputs!$B$23)^(A12-1) | E12: =E11+D12 | F12: =(Inputs!$B$62+Inputs!$B$71)*(1+Inputs!$B$24)^A12 | G12: =Appreciation!F12-C12 | H12: =F12-E12 | I12: =G12-H12
A13: 9 | B13: =SUM(Amortization!D101:D112)+SUM(Amortization!G101:G112)+12*(Inputs!$B$67*(1+Inputs!$B$29)^(A13-1)+Inputs!$B$68*(1+Inputs!$B$30)^(A13-1)+Inputs!$B$70)+SUM(Amortization!H101:H112)*Inputs!$B$69+Inputs!$B$16*Appreciation!B13 | C13: =C12+B13 | D13: =Inputs!$B$22*12*(1+Inputs!$B$23)^(A13-1) | E13: =E12+D13 | F13: =(Inputs!$B$62+Inputs!$B$71)*(1+Inputs!$B$24)^A13 | G13: =Appreciation!F13-C13 | H13: =F13-E13 | I13: =G13-H13
A14: 10 | B14: =SUM(Amortization!D113:D124)+SUM(Amortization!G113:G124)+12*(Inputs!$B$67*(1+Inputs!$B$29)^(A14-1)+Inputs!$B$68*(1+Inputs!$B$30)^(A14-1)+Inputs!$B$70)+SUM(Amortization!H113:H124)*Inputs!$B$69+Inputs!$B$16*Appreciation!B14 | C14: =C13+B14 | D14: =Inputs!$B$22*12*(1+Inputs!$B$23)^(A14-1) | E14: =E13+D14 | F14: =(Inputs!$B$62+Inputs!$B$71)*(1+Inputs!$B$24)^A14 | G14: =Appreciation!F14-C14 | H14: =F14-E14 | I14: =G14-H14
A15: 11 | B15: =SUM(Amortization!D125:D136)+SUM(Amortization!G125:G136)+12*(Inputs!$B$67*(1+Inputs!$B$29)^(A15-1)+Inputs!$B$68*(1+Inputs!$B$30)^(A15-1)+Inputs!$B$70)+SUM(Amortization!H125:H136)*Inputs!$B$69+Inputs!$B$16*Appreciation!B15 | C15: =C14+B15 | D15: =Inputs!$B$22*12*(1+Inputs!$B$23)^(A15-1) | E15: =E14+D15 | F15: =(Inputs!$B$62+Inputs!$B$71)*(1+Inputs!$B$24)^A15 | G15: =Appreciation!F15-C15 | H15: =F15-E15 | I15: =G15-H15
A16: 12 | B16: =SUM(Amortization!D137:D148)+SUM(Amortization!G137:G148)+12*(Inputs!$B$67*(1+Inputs!$B$29)^(A16-1)+Inputs!$B$68*(1+Inputs!$B$30)^(A16-1)+Inputs!$B$70)+SUM(Amortization!H137:H148)*Inputs!$B$69+Inputs!$B$16*Appreciation!B16 | C16: =C15+B16 | D16: =Inputs!$B$22*12*(1+Inputs!$B$23)^(A16-1) | E16: =E15+D16 | F16: =(Inputs!$B$62+Inputs!$B$71)*(1+Inputs!$B$24)^A16 | G16: =Appreciation!F16-C16 | H16: =F16-E16 | I16: =G16-H16
A17: 13 | B17: =SUM(Amortization!D149:D160)+SUM(Amortization!G149:G160)+12*(Inputs!$B$67*(1+Inputs!$B$29)^(A17-1)+Inputs!$B$68*(1+Inputs!$B$30)^(A17-1)+Inputs!$B$70)+SUM(Amortization!H149:H160)*Inputs!$B$69+Inputs!$B$16*Appreciation!B17 | C17: =C16+B17 | D17: =Inputs!$B$22*12*(1+Inputs!$B$23)^(A17-1) | E17: =E16+D17 | F17: =(Inputs!$B$62+Inputs!$B$71)*(1+Inputs!$B$24)^A17 | G17: =Appreciation!F17-C17 | H17: =F17-E17 | I17: =G17-H17
A18: 14 | B18: =SUM(Amortization!D161:D172)+SUM(Amortization!G161:G172)+12*(Inputs!$B$67*(1+Inputs!$B$29)^(A18-1)+Inputs!$B$68*(1+Inputs!$B$30)^(A18-1)+Inputs!$B$70)+SUM(Amortization!H161:H172)*Inputs!$B$69+Inputs!$B$16*Appreciation!B18 | C18: =C17+B18 | D18: =Inputs!$B$22*12*(1+Inputs!$B$23)^(A18-1) | E18: =E17+D18 | F18: =(Inputs!$B$62+Inputs!$B$71)*(1+Inputs!$B$24)^A18 | G18: =Appreciation!F18-C18 | H18: =F18-E18 | I18: =G18-H18
A19: 15 | B19: =SUM(Amortization!D173:D184)+SUM(Amortization!G173:G184)+12*(Inputs!$B$67*(1+Inputs!$B$29)^(A19-1)+Inputs!$B$68*(1+Inputs!$B$30)^(A19-1)+Inputs!$B$70)+SUM(Amortization!H173:H184)*Inputs!$B$69+Inputs!$B$16*Appreciation!B19 | C19: =C18+B19 | D19: =Inputs!$B$22*12*(1+Inputs!$B$23)^(A19-1) | E19: =E18+D19 | F19: =(Inputs!$B$62+Inputs!$B$71)*(1+Inputs!$B$24)^A19 | G19: =Appreciation!F19-C19 | H19: =F19-E19 | I19: =G19-H19
A20: 16 | B20: =SUM(Amortization!D185:D196)+SUM(Amortization!G185:G196)+12*(Inputs!$B$67*(1+Inputs!$B$29)^(A20-1)+Inputs!$B$68*(1+Inputs!$B$30)^(A20-1)+Inputs!$B$70)+SUM(Amortization!H185:H196)*Inputs!$B$69+Inputs!$B$16*Appreciation!B20 | C20: =C19+B20 | D20: =Inputs!$B$22*12*(1+Inputs!$B$23)^(A20-1) | E20: =E19+D20 | F20: =(Inputs!$B$62+Inputs!$B$71)*(1+Inputs!$B$24)^A20 | G20: =Appreciation!F20-C20 | H20: =F20-E20 | I20: =G20-H20
A21: 17 | B21: =SUM(Amortization!D197:D208)+SUM(Amortization!G197:G208)+12*(Inputs!$B$67*(1+Inputs!$B$29)^(A21-1)+Inputs!$B$68*(1+Inputs!$B$30)^(A21-1)+Inputs!$B$70)+SUM(Amortization!H197:H208)*Inputs!$B$69+Inputs!$B$16*Appreciation!B21 | C21: =C20+B21 | D21: =Inputs!$B$22*12*(1+Inputs!$B$23)^(A21-1) | E21: =E20+D21 | F21: =(Inputs!$B$62+Inputs!$B$71)*(1+Inputs!$B$24)^A21 | G21: =Appreciation!F21-C21 | H21: =F21-E21 | I21: =G21-H21
A22: 18 | B22: =SUM(Amortization!D209:D220)+SUM(Amortization!G209:G220)+12*(Inputs!$B$67*(1+Inputs!$B$29)^(A22-1)+Inputs!$B$68*(1+Inputs!$B$30)^(A22-1)+Inputs!$B$70)+SUM(Amortization!H209:H220)*Inputs!$B$69+Inputs!$B$16*Appreciation!B22 | C22: =C21+B22 | D22: =Inputs!$B$22*12*(1+Inputs!$B$23)^(A22-1) | E22: =E21+D22 | F22: =(Inputs!$B$62+Inputs!$B$71)*(1+Inputs!$B$24)^A22 | G22: =Appreciation!F22-C22 | H22: =F22-E22 | I22: =G22-H22
A23: 19 | B23: =SUM(Amortization!D221:D232)+SUM(Amortization!G221:G232)+12*(Inputs!$B$67*(1+Inputs!$B$29)^(A23-1)+Inputs!$B$68*(1+Inputs!$B$30)^(A23-1)+Inputs!$B$70)+SUM(Amortization!H221:H232)*Inputs!$B$69+Inputs!$B$16*Appreciation!B23 | C23: =C22+B23 | D23: =Inputs!$B$22*12*(1+Inputs!$B$23)^(A23-1) | E23: =E22+D23 | F23: =(Inputs!$B$62+Inputs!$B$71)*(1+Inputs!$B$24)^A23 | G23: =Appreciation!F23-C23 | H23: =F23-E23 | I23: =G23-H23
A24: 20 | B24: =SUM(Amortization!D233:D244)+SUM(Amortization!G233:G244)+12*(Inputs!$B$67*(1+Inputs!$B$29)^(A24-1)+Inputs!$B$68*(1+Inputs!$B$30)^(A24-1)+Inputs!$B$70)+SUM(Amortization!H233:H244)*Inputs!$B$69+Inputs!$B$16*Appreciation!B24 | C24: =C23+B24 | D24: =Inputs!$B$22*12*(1+Inputs!$B$23)^(A24-1) | E24: =E23+D24 | F24: =(Inputs!$B$62+Inputs!$B$71)*(1+Inputs!$B$24)^A24 | G24: =Appreciation!F24-C24 | H24: =F24-E24 | I24: =G24-H24
A25: 21 | B25: =SUM(Amortization!D245:D256)+SUM(Amortization!G245:G256)+12*(Inputs!$B$67*(1+Inputs!$B$29)^(A25-1)+Inputs!$B$68*(1+Inputs!$B$30)^(A25-1)+Inputs!$B$70)+SUM(Amortization!H245:H256)*Inputs!$B$69+Inputs!$B$16*Appreciation!B25 | C25: =C24+B25 | D25: =Inputs!$B$22*12*(1+Inputs!$B$23)^(A25-1) | E25: =E24+D25 | F25: =(Inputs!$B$62+Inputs!$B$71)*(1+Inputs!$B$24)^A25 | G25: =Appreciation!F25-C25 | H25: =F25-E25 | I25: =G25-H25
A26: 22 | B26: =SUM(Amortization!D257:D268)+SUM(Amortization!G257:G268)+12*(Inputs!$B$67*(1+Inputs!$B$29)^(A26-1)+Inputs!$B$68*(1+Inputs!$B$30)^(A26-1)+Inputs!$B$70)+SUM(Amortization!H257:H268)*Inputs!$B$69+Inputs!$B$16*Appreciation!B26 | C26: =C25+B26 | D26: =Inputs!$B$22*12*(1+Inputs!$B$23)^(A26-1) | E26: =E25+D26 | F26: =(Inputs!$B$62+Inputs!$B$71)*(1+Inputs!$B$24)^A26 | G26: =Appreciation!F26-C26 | H26: =F26-E26 | I26: =G26-H26
A27: 23 | B27: =SUM(Amortization!D269:D280)+SUM(Amortization!G269:G280)+12*(Inputs!$B$67*(1+Inputs!$B$29)^(A27-1)+Inputs!$B$68*(1+Inputs!$B$30)^(A27-1)+Inputs!$B$70)+SUM(Amortization!H269:H280)*Inputs!$B$69+Inputs!$B$16*Appreciation!B27 | C27: =C26+B27 | D27: =Inputs!$B$22*12*(1+Inputs!$B$23)^(A27-1) | E27: =E26+D27 | F27: =(Inputs!$B$62+Inputs!$B$71)*(1+Inputs!$B$24)^A27 | G27: =Appreciation!F27-C27 | H27: =F27-E27 | I27: =G27-H27
A28: 24 | B28: =SUM(Amortization!D281:D292)+SUM(Amortization!G281:G292)+12*(Inputs!$B$67*(1+Inputs!$B$29)^(A28-1)+Inputs!$B$68*(1+Inputs!$B$30)^(A28-1)+Inputs!$B$70)+SUM(Amortization!H281:H292)*Inputs!$B$69+Inputs!$B$16*Appreciation!B28 | C28: =C27+B28 | D28: =Inputs!$B$22*12*(1+Inputs!$B$23)^(A28-1) | E28: =E27+D28 | F28: =(Inputs!$B$62+Inputs!$B$71)*(1+Inputs!$B$24)^A28 | G28: =Appreciation!F28-C28 | H28: =F28-E28 | I28: =G28-H28
A29: 25 | B29: =SUM(Amortization!D293:D304)+SUM(Amortization!G293:G304)+12*(Inputs!$B$67*(1+Inputs!$B$29)^(A29-1)+Inputs!$B$68*(1+Inputs!$B$30)^(A29-1)+Inputs!$B$70)+SUM(Amortization!H293:H304)*Inputs!$B$69+Inputs!$B$16*Appreciation!B29 | C29: =C28+B29 | D29: =Inputs!$B$22*12*(1+Inputs!$B$23)^(A29-1) | E29: =E28+D29 | F29: =(Inputs!$B$62+Inputs!$B$71)*(1+Inputs!$B$24)^A29 | G29: =Appreciation!F29-C29 | H29: =F29-E29 | I29: =G29-H29
A30: 26 | B30: =SUM(Amortization!D305:D316)+SUM(Amortization!G305:G316)+12*(Inputs!$B$67*(1+Inputs!$B$29)^(A30-1)+Inputs!$B$68*(1+Inputs!$B$30)^(A30-1)+Inputs!$B$70)+SUM(Amortization!H305:H316)*Inputs!$B$69+Inputs!$B$16*Appreciation!B30 | C30: =C29+B30 | D30: =Inputs!$B$22*12*(1+Inputs!$B$23)^(A30-1) | E30: =E29+D30 | F30: =(Inputs!$B$62+Inputs!$B$71)*(1+Inputs!$B$24)^A30 | G30: =Appreciation!F30-C30 | H30: =F30-E30 | I30: =G30-H30
A31: 27 | B31: =SUM(Amortization!D317:D328)+SUM(Amortization!G317:G328)+12*(Inputs!$B$67*(1+Inputs!$B$29)^(A31-1)+Inputs!$B$68*(1+Inputs!$B$30)^(A31-1)+Inputs!$B$70)+SUM(Amortization!H317:H328)*Inputs!$B$69+Inputs!$B$16*Appreciation!B31 | C31: =C30+B31 | D31: =Inputs!$B$22*12*(1+Inputs!$B$23)^(A31-1) | E31: =E30+D31 | F31: =(Inputs!$B$62+Inputs!$B$71)*(1+Inputs!$B$24)^A31 | G31: =Appreciation!F31-C31 | H31: =F31-E31 | I31: =G31-H31
A32: 28 | B32: =SUM(Amortization!D329:D340)+SUM(Amortization!G329:G340)+12*(Inputs!$B$67*(1+Inputs!$B$29)^(A32-1)+Inputs!$B$68*(1+Inputs!$B$30)^(A32-1)+Inputs!$B$70)+SUM(Amortization!H329:H340)*Inputs!$B$69+Inputs!$B$16*Appreciation!B32 | C32: =C31+B32 | D32: =Inputs!$B$22*12*(1+Inputs!$B$23)^(A32-1) | E32: =E31+D32 | F32: =(Inputs!$B$62+Inputs!$B$71)*(1+Inputs!$B$24)^A32 | G32: =Appreciation!F32-C32 | H32: =F32-E32 | I32: =G32-H32
A33: 29 | B33: =SUM(Amortization!D341:D352)+SUM(Amortization!G341:G352)+12*(Inputs!$B$67*(1+Inputs!$B$29)^(A33-1)+Inputs!$B$68*(1+Inputs!$B$30)^(A33-1)+Inputs!$B$70)+SUM(Amortization!H341:H352)*Inputs!$B$69+Inputs!$B$16*Appreciation!B33 | C33: =C32+B33 | D33: =Inputs!$B$22*12*(1+Inputs!$B$23)^(A33-1) | E33: =E32+D33 | F33: =(Inputs!$B$62+Inputs!$B$71)*(1+Inputs!$B$24)^A33 | G33: =Appreciation!F33-C33 | H33: =F33-E33 | I33: =G33-H33
A34: 30 | B34: =SUM(Amortization!D353:D364)+SUM(Amortization!G353:G364)+12*(Inputs!$B$67*(1+Inputs!$B$29)^(A34-1)+Inputs!$B$68*(1+Inputs!$B$30)^(A34-1)+Inputs!$B$70)+SUM(Amortization!H353:H364)*Inputs!$B$69+Inputs!$B$16*Appreciation!B34 | C34: =C33+B34 | D34: =Inputs!$B$22*12*(1+Inputs!$B$23)^(A34-1) | E34: =E33+D34 | F34: =(Inputs!$B$62+Inputs!$B$71)*(1+Inputs!$B$24)^A34 | G34: =Appreciation!F34-C34 | H34: =F34-E34 | I34: =G34-H34

Sheet Affordability
A1: Affordability — Minimum Required Household Income
A2: Back-solves the gross annual income needed for this payment under various DTI standards.
A4: Monthly housing (PITI + PMI + HOA) | B4: =Inputs!$B$81
A5: Other monthly debts | B5: =Inputs!$B$26
A6: Total monthly obligations | B6: =Affordability!$B$4+Affordability!$B$5
A8: Standard | B8: Front-end % | C8: Back-end % | D8: Req. gross/year | E8: Req. gross/month | F8: Comment
A9: Conservative (Ramsey 25%) | B9: 0.25 | C9: 0.25 | D9: =MAX(Affordability!$B$4/B9,Affordability!$B$6/C9)*12 | E9: =MAX(Affordability!$B$4/B9,Affordability!$B$6/C9) | F9: Most conservative; leaves room for everything else.
A10: Classic 28/36 rule | B10: 0.28 | C10: 0.36 | D10: =MAX(Affordability!$B$4/B10,Affordability!$B$6/C10)*12 | E10: =MAX(Affordability!$B$4/B10,Affordability!$B$6/C10) | F10: Conventional lender baseline.
A11: FHA upper limit (31/43) | B11: 0.31 | C11: 0.43 | D11: =MAX(Affordability!$B$4/B11,Affordability!$B$6/C11)*12 | E11: =MAX(Affordability!$B$4/B11,Affordability!$B$6/C11) | F11: Stretched but qualifies for FHA.
A12: Aggressive (35/45) | B12: 0.35 | C12: 0.45 | D12: =MAX(Affordability!$B$4/B12,Affordability!$B$6/C12)*12 | E12: =MAX(Affordability!$B$4/B12,Affordability!$B$6/C12) | F12: Risky — leaves little margin for shocks.
A13: Custom (from Inputs) | B13: =Inputs!$B$27 | C13: =Inputs!$B$27+0.08 | D13: =MAX(Affordability!$B$4/B13,Affordability!$B$6/C13)*12 | E13: =MAX(Affordability!$B$4/B13,Affordability!$B$6/C13) | F13: Your custom front-end. Back-end = front + 8 pts.
A15: Formula: required_income = MAX( housing/front_DTI, total_obligations/back_DTI ) × 12

Sheet Cash to Close
A1: Cash to Close
A2: Cash needed at closing and recommended liquid retention.
A4: STEP 1 — Cash needed at closing
A5: Down payment | B5: =Inputs!$B$62 | D5: Spent at close
A6: Closing costs | B6: =Inputs!$B$71 | D6: Spent at close
A7: Move-in / repairs | B7: =Inputs!$B$32 | D7: Spent at close
A8: Lender reserves | B8: =Inputs!$B$81*Inputs!$B$33 | D8: Stays in account post-close
A9: Total cash needed at close | B9: =SUM(B5:B8)
A11: Liquid remaining after close | B11: =Inputs!$B$35-Inputs!$B$62-Inputs!$B$71-Inputs!$B$32 | D11: Includes lender reserves; those stay liquid
A13: STEP 2 — Recommended liquid retention
A14: Monthly cost of living (housing + other) | B14: =Inputs!$B$37+Inputs!$B$81
A15: Emergency fund target | B15: ='Cash to Close'!$B$14*Inputs!$B$38 | D15: Full living costs × emergency months
A16: Lender reserves (subset of emergency fund) | B16: =Inputs!$B$81*Inputs!$B$33
A17: Total liquid to retain | B17: =MAX('Cash to Close'!$B$15,Inputs!$B$81*Inputs!$B$33)

Sheet Buy Today
A1: Buy Today Analysis
A2: What your position looks like if you buy today with current assets.
A4: LIQUIDITY CHECK
A5: Current liquid assets | B5: =Inputs!$B$35
A6: % of liquid used for closing | B6: =IF(Inputs!$B$35>0,'Cash to Close'!$B$9/Inputs!$B$35,1)
A7: Liquid remaining after close | B7: ='Cash to Close'!$B$11
A8: Emergency fund target | B8: ='Cash to Close'!$B$15
A10: CONCENTRATION CAP
A11: Planned down payment | B11: =Inputs!$B$62
A12: Liquid required at purchase | B12: =IF(Inputs!$B$39>0,Inputs!$B$62/Inputs!$B$39,0) | C12: Planned DP ÷ Max % of liquid
A13: Current liquid | B13: =Inputs!$B$35
A14: Surplus / shortfall | B14: =Inputs!$B$35-'Buy Today'!$B$12 | C14: Positive = surplus. Negative = need more liquid.
A15: Monthly return (for savings calc) | B15: =(1+Inputs!$B$24)^(1/12)-1
A16: Time to reach goal | B16: =IF('Buy Today'!$B$14>=0,"Already there",IF(Inputs!$B$36<=0,"Need savings",IFERROR(NPER('Buy Today'!$B$15,-Inputs!$B$36,0,-'Buy Today'!$B$14)/12,0)&" yr")) | C16: Years to save to reach required liquid
A17: Status | B17: =IF(Inputs!$B$35>='Buy Today'!$B$12,"OK — within concentration cap","Below — save more, lower DP, or raise cap")

Sheet Tax Benefits
A1: Tax Benefits — Mortgage Interest, SALT, and Capital Gains
A2: Federal benefits from itemizing vs standard, plus $250K/$500K Section 121 exclusion on sale.
A4: Item | B4: Year 1 | C4: Year 5 | D4: Year 10 | E4: Year 30
A5: Mortgage interest paid | B5: =SUM(Amortization!F5:F16) | C5: =SUM(Amortization!F53:F64) | D5: =SUM(Amortization!F113:F124) | E5: =SUM(Amortization!F353:F364) | F5: From amortization
A6: Deductible interest (post-TCJA $750K cap) | B6: =B5*IF(Inputs!$B$63>750000,750000/Inputs!$B$63,1) | C6: =C5*IF(Inputs!$B$63>750000,750000/Inputs!$B$63,1) | D6: =D5*IF(Inputs!$B$63>750000,750000/Inputs!$B$63,1) | E6: =E5*IF(Inputs!$B$63>750000,750000/Inputs!$B$63,1) | F6: If loan > $750K, scale interest proportionally
A7: Property tax (escalated) | B7: =Inputs!$B$10*Inputs!$B$5*(1+Inputs!$B$29)^(1-1) | C7: =Inputs!$B$10*Inputs!$B$5*(1+Inputs!$B$29)^(5-1) | D7: =Inputs!$B$10*Inputs!$B$5*(1+Inputs!$B$29)^(10-1) | E7: =Inputs!$B$10*Inputs!$B$5*(1+Inputs!$B$29)^(30-1) | F7: Grows at tax-growth rate from Inputs
A8: SALT deductible (capped at $10K) | B8: =MIN(10000,B7+Inputs!$B$43) | C8: =MIN(10000,C7+Inputs!$B$43) | D8: =MIN(10000,D7+Inputs!$B$43) | E8: =MIN(10000,E7+Inputs!$B$43) | F8: Property tax + other SALT, capped at $10K
A9: Itemized total | B9: =B6+B8 | C9: =C6+C8 | D9: =D6+D8 | E9: =E6+E8
A10: Standard deduction (2024) | B10: =IF(Inputs!$B$41="M",29200,14600) | C10: =IF(Inputs!$B$41="M",29200,14600) | D10: =IF(Inputs!$B$41="M",29200,14600) | E10: =IF(Inputs!$B$41="M",29200,14600)
A11: Federal tax savings | B11: =MAX(0,B9-B10)*Inputs!$B$42 | C11: =MAX(0,C9-C10)*Inputs!$B$42 | D11: =MAX(0,D9-D10)*Inputs!$B$42 | E11: =MAX(0,E9-E10)*Inputs!$B$42
A13: CAPITAL GAINS AT SALE (Year 30)
A14: Sale value (year 30) | B14: =Appreciation!B34 | F14: Home appreciated at the rate in Inputs
A15: Selling costs | B15: =Appreciation!E34 | F15: Pct of sale value
A16: Cost basis (price + closing) | B16: =Inputs!$B$5+Inputs!$B$71 | F16: Original price + closing costs
A17: Gross gain | B17: =MAX(0,B14-B15-B16) | F17: Sale − selling costs − basis
A18: Section 121 exclusion | B18: =IF(Inputs!$B$41="M",500000,250000) | F18: $500K MFJ / $250K single
A19: Taxable gain | B19: =MAX(0,B17-B18) | F19: Excess over exclusion
A20: Federal LTCG tax | B20: =B19*Inputs!$B$44 | F20: Taxable gain × LTCG rate
A21: Net equity (pre-tax) | B21: =Appreciation!F34 | F21: From Appreciation sheet
A22: After-tax net equity | B22: =B21-B20 | F22: What you actually walk away with

Sheet Retirement Tradeoff
A1: Retirement Tradeoff Analysis
A2: How your housing costs affect retirement savings capacity.
A4: CURRENT RETIREMENT POSITION
A5: Gross monthly income | B5: =Inputs!$B$46/12
A6: Current 401k contribution ($/mo) | B6: =Inputs!$B$46*Inputs!$B$47/12
A7: Employer match received ($/mo) | B7: =MIN(Inputs!$B$46*Inputs!$B$47,Inputs!$B$46*Inputs!$B$49)*Inputs!$B$48/12
A8: Total going to retirement ($/mo) | B8: ='Retirement Tradeoff'!$B$6+'Retirement Tradeoff'!$B$7
A10: HOUSING COST IMPACT
A11: Monthly housing (PITI) | B11: =Inputs!$B$81
A12: Housing as % of gross income | B12: =Inputs!$B$81/'Retirement Tradeoff'!$B$5 | C12: Target: <28% (ideal), <35% (max)
A13: Retirement as % of gross income | B13: ='Retirement Tradeoff'!$B$8/'Retirement Tradeoff'!$B$5 | C13: Target: 15-20% including match
A14: Combined (housing + retirement %) | B14: ='Retirement Tradeoff'!$B$12+Inputs!$B$47
A16: OPPORTUNITY COST
A17: Current rent (from inputs) | B17: =Inputs!$B$22
A18: Monthly difference (own − rent) | B18: =Inputs!$B$81-Inputs!$B$22
A19: If diff invested monthly for N years | B19: =FV(Inputs!$B$50/12,Inputs!$B$51*12,-'Retirement Tradeoff'!$B$18,0) | C19: What you'd have if renting + investing the difference
A21: RETIREMENT BALANCE PROJECTION
A22: Current contribution trajectory | B22: =FV(Inputs!$B$50/12,Inputs!$B$51*12,-'Retirement Tradeoff'!$B$8,0) | C22: FV of current contributions over retirement years
A23: If you maxed 401k ($23K/yr) + match | B23: =FV(Inputs!$B$50/12,Inputs!$B$51*12,-(23000/12+MIN(23000/12,Inputs!$B$46*Inputs!$B$49/12)*Inputs!$B$48),0)
A24: Retirement shortfall from current plan | B24: ='Retirement Tradeoff'!$B$23-'Retirement Tradeoff'!$B$22 | C24: Difference between max and current trajectory
A26: VERDICT
A27: Assessment | B27: =IF('Retirement Tradeoff'!$B$12>0.35,"Housing crowding retirement",IF(Inputs!$B$47<Inputs!$B$49,"Increase 401k to capture full match",IF('Retirement Tradeoff'!$B$12<0.28,"Good balance","Acceptable but watch spending")))

Sheet ROI Analysis
A1: ROI Analysis — Return on Investment at Sale
A2: Three ways to measure your return if you sell the home at different points.
A4: Metric | B4: Year 5 | C4: Year 10 | D4: Year 15 | E4: Year 20 | F4: Year 30
A5: Initial cash outlay (DP + closing) | B5: =Inputs!$B$62+Inputs!$B$71 | C5: =Inputs!$B$62+Inputs!$B$71 | D5: =Inputs!$B$62+Inputs!$B$71 | E5: =Inputs!$B$62+Inputs!$B$71 | F5: =Inputs!$B$62+Inputs!$B$71
A6: Cumulative payments (P&I+Tax+Ins+PMI+HOA) | B6: =SUM(Amortization!D5:D64)+SUM(Amortization!G5:G64)+Inputs!$B$67*60+Inputs!$B$68*60+SUMPRODUCT(Amortization!H5:H64)*Inputs!$B$69+Inputs!$B$70*60 | C6: =SUM(Amortization!D5:D124)+SUM(Amortization!G5:G124)+Inputs!$B$67*120+Inputs!$B$68*120+SUMPRODUCT(Amortization!H5:H124)*Inputs!$B$69+Inputs!$B$70*120 | D6: =SUM(Amortization!D5:D184)+SUM(Amortization!G5:G184)+Inputs!$B$67*180+Inputs!$B$68*180+SUMPRODUCT(Amortization!H5:H184)*Inputs!$B$69+Inputs!$B$70*180 | E6: =SUM(Amortization!D5:D244)+SUM(Amortization!G5:G244)+Inputs!$B$67*240+Inputs!$B$68*240+SUMPRODUCT(Amortization!H5:H244)*Inputs!$B$69+Inputs!$B$70*240 | F6: =SUM(Amortization!D5:D364)+SUM(Amortization!G5:G364)+Inputs!$B$67*360+Inputs!$B$68*360+SUMPRODUCT(Amortization!H5:H364)*Inputs!$B$69+Inputs!$B$70*360
A7: Cumulative maintenance | B7: =Inputs!$B$16*Inputs!$B$5*((1+Inputs!$B$15)^5+1)/2*5 | C7: =Inputs!$B$16*Inputs!$B$5*((1+Inputs!$B$15)^10+1)/2*10 | D7: =Inputs!$B$16*Inputs!$B$5*((1+Inputs!$B$15)^15+1)/2*15 | E7: =Inputs!$B$16*Inputs!$B$5*((1+Inputs!$B$15)^20+1)/2*20 | F7: =Inputs!$B$16*Inputs!$B$5*((1+Inputs!$B$15)^30+1)/2*30
A8: Total cash invested | B8: =B5+B6+B7 | C8: =B5+C6+C7 | D8: =B5+D6+D7 | E8: =B5+E6+E7 | F8: =B5+F6+F7
A9: Home value at sale | B9: =Inputs!$B$5*(1+Inputs!$B$15)^5 | C9: =Inputs!$B$5*(1+Inputs!$B$15)^10 | D9: =Inputs!$B$5*(1+Inputs!$B$15)^15 | E9: =Inputs!$B$5*(1+Inputs!$B$15)^20 | F9: =Inputs!$B$5*(1+Inputs!$B$15)^30
A10: Loan balance at sale | B10: =IFERROR(INDEX(Amortization!I:I,64),0) | C10: =IFERROR(INDEX(Amortization!I:I,124),0) | D10: =IFERROR(INDEX(Amortization!I:I,184),0) | E10: =IFERROR(INDEX(Amortization!I:I,244),0) | F10: =IFERROR(INDEX(Amortization!I:I,364),0)
A11: Selling costs | B11: =B9*Inputs!$B$18 | C11: =C9*Inputs!$B$18 | D11: =D9*Inputs!$B$18 | E11: =E9*Inputs!$B$18 | F11: =F9*Inputs!$B$18
A12: Net equity at sale (after selling costs) | B12: =B9-B10-B11 | C12: =C9-C10-C11 | D12: =D9-D10-D11 | E12: =E9-E10-E11 | F12: =F9-F10-F11
A14: RETURN METRICS
A15: 1. Simple ROI | B15: =(B12-B8)/B8 | C15: =(C12-C8)/C8 | D15: =(D12-D8)/D8 | E15: =(E12-E8)/E8 | F15: =(F12-F8)/F8 | G15: (Net Equity − Total Cash) / Total Cash
A16: 2. CAGR (on initial cash only) | B16: =IFERROR((B12/'ROI Analysis'!$B$5)^(1/5)-1,0) | C16: =IFERROR((C12/'ROI Analysis'!$B$5)^(1/10)-1,0) | D16: =IFERROR((D12/'ROI Analysis'!$B$5)^(1/15)-1,0) | E16: =IFERROR((E12/'ROI Analysis'!$B$5)^(1/20)-1,0) | F16: =IFERROR((F12/'ROI Analysis'!$B$5)^(1/30)-1,0) | G16: (Net Equity / Initial Cash)^(1/years) − 1
A17: 3. IRR (estimated) | B17: =IFERROR(RATE(5*12,-(B8-'ROI Analysis'!$B$5)/5/12,'ROI Analysis'!$B$5,-B12)*12,0) | C17: =IFERROR(RATE(10*12,-(C8-'ROI Analysis'!$B$5)/10/12,'ROI Analysis'!$B$5,-C12)*12,0) | D17: =IFERROR(RATE(15*12,-(D8-'ROI Analysis'!$B$5)/15/12,'ROI Analysis'!$B$5,-D12)*12,0) | E17: =IFERROR(RATE(20*12,-(E8-'ROI Analysis'!$B$5)/20/12,'ROI Analysis'!$B$5,-E12)*12,0) | F17: =IFERROR(RATE(30*12,-(F8-'ROI Analysis'!$B$5)/30/12,'ROI Analysis'!$B$5,-F12)*12,0) | G17: Annualized return on all cash flows (estimated)
A19: MARKET COMPARISON
A20: If total cash invested in market instead | B20: ='ROI Analysis'!$B$5*(1+Inputs!$B$24)^5+FV(Inputs!$B$24/12,5*12,-(B8-'ROI Analysis'!$B$5)/5/12,0) | C20: ='ROI Analysis'!$B$5*(1+Inputs!$B$24)^10+FV(Inputs!$B$24/12,10*12,-(C8-'ROI Analysis'!$B$5)/10/12,0) | D20: ='ROI Analysis'!$B$5*(1+Inputs!$B$24)^15+FV(Inputs!$B$24/12,15*12,-(D8-'ROI Analysis'!$B$5)/15/12,0) | E20: ='ROI Analysis'!$B$5*(1+Inputs!$B$24)^20+FV(Inputs!$B$24/12,20*12,-(E8-'ROI Analysis'!$B$5)/20/12,0) | F20: ='ROI Analysis'!$B$5*(1+Inputs!$B$24)^30+FV(Inputs!$B$24/12,30*12,-(F8-'ROI Analysis'!$B$5)/30/12,0)
A21: Home equity vs. market investment | B21: =B12-B20 | C21: =C12-C20 | D21: =D12-D20 | E21: =E12-E20 | F21: =F12-F20 | G21: Positive = home wins, Negative = market wins

Sheet Refinance
A1: Refinance Analysis
A2: Compares refinancing at the chosen year vs. keeping the original loan.
A3: =IF(Inputs!$B$53=1,"Status: refi simulation ENABLED","Status: refi DISABLED — set Include refi? to 1 on Inputs sheet to enable")
A4: Balance at refi point | B4: =INDEX(Amortization!I:I,4+Inputs!$B$54*12)
A5: Cash-out amount | B5: =Inputs!$B$58
A6: Refi closing costs | B6: =(Refinance!$B$4+Inputs!$B$58)*Inputs!$B$57
A7: New loan amount | B7: =Refinance!$B$4+Inputs!$B$58+IF(Inputs!$B$59=1,Refinance!$B$6,0)
A8: Cash needed at refi (out of pocket) | B8: =IF(Inputs!$B$59=1,0,Refinance!$B$6)
A10: Metric | B10: Keep current loan | C10: Refinance | D10: Delta
A11: Monthly P&I | B11: =Inputs!$B$66 | C11: =-PMT(Inputs!$B$55/12,Inputs!$B$56*12,Refinance!$B$7) | D11: =C11-B11
A12: Months remaining | B12: =Inputs!$B$8*12-Inputs!$B$54*12 | C12: =Inputs!$B$56*12 | D12: =C12-B12
A13: Total interest remaining | B13: =SUM(INDEX(Amortization!F:F,4+Inputs!$B$54*12+1):INDEX(Amortization!F:F,4+Inputs!$B$8*12)) | C13: =Refinance!$C$11*Inputs!$B$56*12-Refinance!$B$7 | D13: =C13-B13
A14: Total P+I remaining | B14: =Inputs!$B$66*(Inputs!$B$8*12-Inputs!$B$54*12) | C14: =Refinance!$C$11*Inputs!$B$56*12+Refinance!$B$8 | D14: =C14-B14
A16: SUMMARY
A17: Monthly savings | B17: =Inputs!$B$66-Refinance!$C$11
A18: Break-even (months) | B18: =IFERROR(IF(Refinance!$B$17<=0,"Never",IF(Refinance!$B$8=0,0,Refinance!$B$8/Refinance!$B$17)),"Never")
A19: Lifetime interest saved | B19: =SUM(INDEX(Amortization!F:F,4+Inputs!$B$54*12+1):INDEX(Amortization!F:F,4+Inputs!$B$8*12))-(Refinance!$C$11*Inputs!$B$56*12-Refinance!$B$7) | E19: Positive = saves; negative = extending term costs more total interest
A20: Verdict | B20: =IF(Inputs!$B$53=0,"Disabled (toggle on Inputs)",IF(Inputs!$B$55>=Inputs!$B$7,"Rate not lower — only refi if cash-out needed",IF(Refinance!$B$17<=0,"Higher monthly cost",IF(B19<0,"Lower monthly but more total interest","Refi favorable"))))

Sheet Extra Payment
A1: Extra Payment Impact
A2: Compares 'Current' (with extra) to 'Baseline' (no extra) using the loan you set in Inputs.
B4: Baseline (no extra) | C4: With extra
A5: Loan amount | B5: =Inputs!$B$63 | C5: =Inputs!$B$63
A6: Monthly P&I | B6: =-PMT(Inputs!$B$64,Inputs!$B$65,Inputs!$B$63) | C6: =-PMT(Inputs!$B$64,Inputs!$B$65,Inputs!$B$63)
A7: Extra per month | B7: 0 | C7: =Inputs!$B$20
A8: Effective payment | B8: =B6 | C8: =C6+C7
A9: Months to payoff | B9: =Inputs!$B$65 | C9: =IFERROR(NPER(Inputs!$B$64,-(B6+Inputs!$B$20),Inputs!$B$63),Inputs!$B$65)
A10: Years to payoff | B10: =B9/12 | C10: =C9/12
A11: Total interest | B11: =B6*B9-Inputs!$B$63 | C11: =(B6+Inputs!$B$20)*C9-Inputs!$B$63
A12: Total paid | B12: =B6*B9 | C12: =(B6+Inputs!$B$20)*C9
A14: Interest saved | B14: =B11-C11
A15: Months saved | B15: =B9-C9
A16: Years saved | B16: =B10-C10

Sheet Scenarios
A1: Scenario Comparison
A2: Three editable scenarios. Edit inputs in B/C/D columns to compare side-by-side.
A4: Assumption | B4: Scenario A | C4: Scenario B | D4: Scenario C
A5: Home price ($) | B5: 500000 | C5: 500000 | D5: 600000
A6: Down payment (%) | B6: 0.2 | C6: 0.1 | D6: 0.2
A7: Interest rate | B7: 0.065 | C7: 0.065 | D7: 0.065
A8: Loan term (years) | B8: 30 | C8: 30 | D8: 15
A9: Extra/month ($) | B9: 0 | C9: 0 | D9: 500
A10: Appreciation (annual) | B10: 0.035 | C10: 0.035 | D10: 0.035
A12: RESULTS
A13: Down payment ($) | B13: =B5*B6 | C13: =C5*C6 | D13: =D5*D6
A14: Loan amount ($) | B14: =B5-B5*B6 | C14: =C5-C5*C6 | D14: =D5-D5*D6
A15: Monthly P&I | B15: =-PMT(B7/12,B8*12,B5*(1-B6)) | C15: =-PMT(C7/12,C8*12,C5*(1-C6)) | D15: =-PMT(D7/12,D8*12,D5*(1-D6))
A16: Monthly tax+ins | B16: =Inputs!$B$67+Inputs!$B$68 | C16: =Inputs!$B$67+Inputs!$B$68 | D16: =Inputs!$B$67+Inputs!$B$68
A17: Total monthly (est) | B17: =-PMT(B7/12,B8*12,B5*(1-B6))+Inputs!$B$10*B5/12+Inputs!$B$68+Inputs!$B$70 | C17: =-PMT(C7/12,C8*12,C5*(1-C6))+Inputs!$B$10*C5/12+Inputs!$B$68+Inputs!$B$70 | D17: =-PMT(D7/12,D8*12,D5*(1-D6))+Inputs!$B$10*D5/12+Inputs!$B$68+Inputs!$B$70
A18: Total interest (no extra) | B18: =-PMT(B7/12,B8*12,B5*(1-B6))*B8*12-(B5*(1-B6)) | C18: =-PMT(C7/12,C8*12,C5*(1-C6))*C8*12-(C5*(1-C6)) | D18: =-PMT(D7/12,D8*12,D5*(1-D6))*D8*12-(D5*(1-D6))
A19: Months to payoff (w/ extra) | B19: =IFERROR(NPER(B7/12,-(-PMT(B7/12,B8*12,B5*(1-B6))+B9),B5*(1-B6)),B8*12) | C19: =IFERROR(NPER(C7/12,-(-PMT(C7/12,C8*12,C5*(1-C6))+C9),C5*(1-C6)),C8*12) | D19: =IFERROR(NPER(D7/12,-(-PMT(D7/12,D8*12,D5*(1-D6))+D9),D5*(1-D6)),D8*12)
A20: Years to payoff (w/ extra) | B20: =IFERROR(NPER(B7/12,-(-PMT(B7/12,B8*12,B5*(1-B6))+B9),B5*(1-B6))/12,B8) | C20: =IFERROR(NPER(C7/12,-(-PMT(C7/12,C8*12,C5*(1-C6))+C9),C5*(1-C6))/12,C8) | D20: =IFERROR(NPER(D7/12,-(-PMT(D7/12,D8*12,D5*(1-D6))+D9),D5*(1-D6))/12,D8)
A21: Home value @ year 30 | B21: =B5*(1+B10)^30 | C21: =C5*(1+C10)^30 | D21: =D5*(1+D10)^30
A22: Home value @ year 10 | B22: =B5*(1+B10)^10 | C22: =C5*(1+C10)^10 | D22: =D5*(1+D10)^10
A23: Min income (Ramsey 25%) | B23: =MAX((-PMT(B7/12,B8*12,B5*(1-B6))+Inputs!$B$10*B5/12+Inputs!$B$68+Inputs!$B$70+IF(B6<0.2,Inputs!$B$13*B5*(1-B6)/12,0))/0.25,((-PMT(B7/12,B8*12,B5*(1-B6))+Inputs!$B$10*B5/12+Inputs!$B$68+Inputs!$B$70+IF(B6<0.2,Inputs!$B$13*B5*(1-B6)/12,0))+Inputs!$B$26)/0.25)*12 | C23: =MAX((-PMT(C7/12,C8*12,C5*(1-C6))+Inputs!$B$10*C5/12+Inputs!$B$68+Inputs!$B$70+IF(C6<0.2,Inputs!$B$13*C5*(1-C6)/12,0))/0.25,((-PMT(C7/12,C8*12,C5*(1-C6))+Inputs!$B$10*C5/12+Inputs!$B$68+Inputs!$B$70+IF(C6<0.2,Inputs!$B$13*C5*(1-C6)/12,0))+Inputs!$B$26)/0.25)*12 | D23: =MAX((-PMT(D7/12,D8*12,D5*(1-D6))+Inputs!$B$10*D5/12+Inputs!$B$68+Inputs!$B$70+IF(D6<0.2,Inputs!$B$13*D5*(1-D6)/12,0))/0.25,((-PMT(D7/12,D8*12,D5*(1-D6))+Inputs!$B$10*D5/12+Inputs!$B$68+Inputs!$B$70+IF(D6<0.2,Inputs!$B$13*D5*(1-D6)/12,0))+Inputs!$B$26)/0.25)*12
A24: Min income (28/36 rule) | B24: =MAX((-PMT(B7/12,B8*12,B5*(1-B6))+Inputs!$B$10*B5/12+Inputs!$B$68+Inputs!$B$70+IF(B6<0.2,Inputs!$B$13*B5*(1-B6)/12,0))/0.28,((-PMT(B7/12,B8*12,B5*(1-B6))+Inputs!$B$10*B5/12+Inputs!$B$68+Inputs!$B$70+IF(B6<0.2,Inputs!$B$13*B5*(1-B6)/12,0))+Inputs!$B$26)/0.36)*12 | C24: =MAX((-PMT(C7/12,C8*12,C5*(1-C6))+Inputs!$B$10*C5/12+Inputs!$B$68+Inputs!$B$70+IF(C6<0.2,Inputs!$B$13*C5*(1-C6)/12,0))/0.28,((-PMT(C7/12,C8*12,C5*(1-C6))+Inputs!$B$10*C5/12+Inputs!$B$68+Inputs!$B$70+IF(C6<0.2,Inputs!$B$13*C5*(1-C6)/12,0))+Inputs!$B$26)/0.36)*12 | D24: =MAX((-PMT(D7/12,D8*12,D5*(1-D6))+Inputs!$B$10*D5/12+Inputs!$B$68+Inputs!$B$70+IF(D6<0.2,Inputs!$B$13*D5*(1-D6)/12,0))/0.28,((-PMT(D7/12,D8*12,D5*(1-D6))+Inputs!$B$10*D5/12+Inputs!$B$68+Inputs!$B$70+IF(D6<0.2,Inputs!$B$13*D5*(1-D6)/12,0))+Inputs!$B$26)/0.36)*12
A25: Min income (FHA 31/43) | B25: =MAX((-PMT(B7/12,B8*12,B5*(1-B6))+Inputs!$B$10*B5/12+Inputs!$B$68+Inputs!$B$70+IF(B6<0.2,Inputs!$B$13*B5*(1-B6)/12,0))/0.31,((-PMT(B7/12,B8*12,B5*(1-B6))+Inputs!$B$10*B5/12+Inputs!$B$68+Inputs!$B$70+IF(B6<0.2,Inputs!$B$13*B5*(1-B6)/12,0))+Inputs!$B$26)/0.43)*12 | C25: =MAX((-PMT(C7/12,C8*12,C5*(1-C6))+Inputs!$B$10*C5/12+Inputs!$B$68+Inputs!$B$70+IF(C6<0.2,Inputs!$B$13*C5*(1-C6)/12,0))/0.31,((-PMT(C7/12,C8*12,C5*(1-C6))+Inputs!$B$10*C5/12+Inputs!$B$68+Inputs!$B$70+IF(C6<0.2,Inputs!$B$13*C5*(1-C6)/12,0))+Inputs!$B$26)/0.43)*12 | D25: =MAX((-PMT(D7/12,D8*12,D5*(1-D6))+Inputs!$B$10*D5/12+Inputs!$B$68+Inputs!$B$70+IF(D6<0.2,Inputs!$B$13*D5*(1-D6)/12,0))/0.31,((-PMT(D7/12,D8*12,D5*(1-D6))+Inputs!$B$10*D5/12+Inputs!$B$68+Inputs!$B$70+IF(D6<0.2,Inputs!$B$13*D5*(1-D6)/12,0))+Inputs!$B$26)/0.43)*12
